<?xml version="1.0" ?>
<sdf version="1.6">
  <model name="zephyr_delta_wing">
    <pose>0 0 0.02577 0 0 0</pose>
    <link name="base_link">
      <inertial>
        <pose>0 -0.12 0 0 0 0</pose>
        <mass>1.5</mass>
        <inertia>
          <ixx>0.083137104</ixx>
          <ixy>0</ixy>
          <iyy>0.387382402</iyy>
          <ixz>0</ixz>
          <iyz>0</iyz>
          <izz>0.469845106</izz>
        </inertia>
      </inertial>
      <visual name="visual">
        <geometry>
          <mesh>
            <uri>model://zephyr_delta_wing/meshes/wing.dae</uri>
            <submesh>
              <name>Wing</name>
              <center>true</center>
            </submesh>
          </mesh>
        </geometry>
      </visual>
      <collision name="body_collision">
        <geometry>
          <mesh>
            <uri>model://zephyr_delta_wing/meshes/wing.dae</uri>
            <submesh>
              <name>Wing</name>
              <center>true</center>
            </submesh>
          </mesh>
        </geometry>
      </collision>
      <collision name="right_rudder_collision">
        <pose>-0.76435 0.33918 0.002 -0.03 0 0</pose>
        <geometry>
          <box>
            <size>.005 0.12993 .12688</size>
          </box>
        </geometry>
      </collision>
      <collision name="left_rudder_collision">
        <pose>0.76435 0.33918 0.002 -0.03 0 0</pose>
        <geometry>
          <box>
            <size>.005 0.12993 .12688</size>
          </box>
        </geometry>
      </collision>
    </link>
    <link name='delta_wing/imu_link'>
      <pose>0 0 0 0 0 0</pose>
      <inertial>
        <pose>0 0 0 0 0 0</pose>
        <mass>0.015</mass>
        <inertia>
          <ixx>1e-05</ixx>
          <ixy>0</ixy>
          <ixz>0</ixz>
          <iyy>1e-05</iyy>
          <iyz>0</iyz>
          <izz>1e-05</izz>
        </inertia>
      </inertial>
    </link>
    <joint name='delta_wing/imu_joint' type='revolute'>
      <child>delta_wing/imu_link</child>
      <parent>base_link</parent>
      <axis>
        <xyz>1 0 0</xyz>
        <limit>
          <lower>0</lower>
          <upper>0</upper>
          <effort>0</effort>
          <velocity>0</velocity>
        </limit>
        <dynamics>
          <spring_reference>0</spring_reference>
          <spring_stiffness>0</spring_stiffness>
        </dynamics>
        <use_parent_model_frame>1</use_parent_model_frame>
      </axis>
    </joint>
    <link name='delta_wing/airspeed_link'>
      <pose>0 0 0 0 0 0</pose>
      <inertial>
        <pose>0 0 0 0 0 0</pose>
        <mass>0.015</mass>
        <inertia>
          <ixx>1e-05</ixx>
          <ixy>0</ixy>
          <ixz>0</ixz>
          <iyy>1e-05</iyy>
          <iyz>0</iyz>
          <izz>1e-05</izz>
        </inertia>
      </inertial>
    </link>
    <joint name='delta_wing/airspeed_joint' type='revolute'>
      <child>delta_wing/airspeed_link</child>
      <parent>base_link</parent>
      <axis>
        <xyz>1 0 0</xyz>
        <limit>
          <lower>0</lower>
          <upper>0</upper>
          <effort>0</effort>
          <velocity>0</velocity>
        </limit>
        <dynamics>
          <spring_reference>0</spring_reference>
          <spring_stiffness>0</spring_stiffness>
        </dynamics>
        <use_parent_model_frame>1</use_parent_model_frame>
      </axis>
    </joint>
    <link name="propeller">
      <pose>0 0.07 0.008 0 1.5707 0</pose>
      <inertial>
        <mass>.05</mass>
        <inertia>
          <ixx>0.000367571</ixx>
          <ixy>0</ixy>
          <iyy>0.00036985</iyy>
          <ixz>0</ixz>
          <iyz>0</iyz>
          <izz>0.000003187</izz>
        </inertia>
      </inertial>
      <visual name="visual">
        <geometry>
          <mesh>
            <uri>model://zephyr_delta_wing/meshes/wing.dae</uri>
            <submesh>
              <name>Propeller</name>
              <center>true</center>
            </submesh>
          </mesh>
        </geometry>
      </visual>
      <collision name="blade1">
        <pose>0 0 0.074205 0 0  0.3</pose>
        <geometry>
          <box>
            <size>0.02561 0.00541 0.14841</size>
          </box>
        </geometry>
      </collision>
      <collision name="blade2">
        <pose>0 0 -0.074205 0 0  -0.3</pose>
        <geometry>
          <box>
            <size>0.02561 0.00541 0.14841</size>
          </box>
        </geometry>
      </collision>
    </link>

    <link name="flap_left">
      <pose>0.4530 .239 0.007 0 0 0</pose>
      <inertial>
        <pose>0 0 0 0 0 0.32445671</pose>
        <mass>.1</mass>
        <inertia>
          <ixx>0.000102319</ixx>
          <ixy>0</ixy>
          <iyy>0.00334417</iyy>
          <ixz>0</ixz>
          <iyz>0</iyz>
          <izz>0.003446072</izz>
        </inertia>
      </inertial>
      <visual name="visual">
        <geometry>
          <mesh>
            <uri>model://zephyr_delta_wing/meshes/wing.dae</uri>
            <submesh>
              <name>Flap_Left</name>
              <center>true</center>
            </submesh>
          </mesh>
        </geometry>
      </visual>
      <collision name="collision">
        <pose>-0.01 0.01 0 0 0 0.32445671</pose>
        <geometry>
          <box>
            <size>0.633463031 0.110694312 0.005</size>
          </box>
        </geometry>
      </collision>
    </link>

    <link name="flap_right">
      <pose>-0.4530 .239 0.007 0 0 0</pose>
      <inertial>
        <pose>0 0 0 0 0 -0.32445671</pose>
        <mass>.1</mass>
        <inertia>
          <ixx>0.000102319</ixx>
          <ixy>0</ixy>
          <iyy>0.00334417</iyy>
          <ixz>0</ixz>
          <iyz>0</iyz>
          <izz>0.003446072</izz>
        </inertia>
      </inertial>
      <visual name="visual">
        <geometry>
          <mesh>
            <uri>model://zephyr_delta_wing/meshes/wing.dae</uri>
            <submesh>
              <name>Flap_Right</name>
              <center>true</center>
            </submesh>
          </mesh>
        </geometry>
      </visual>
      <collision name="collision">
        <pose>0.01 0.01 0 0 0 -0.32445671</pose>
        <geometry>
          <box>
            <size>0.633463031 0.110694312 0.005</size>
          </box>
        </geometry>
      </collision>
    </link>

    <joint name="propeller_joint" type="revolute">
      <parent>base_link</parent>
      <child>propeller</child>
      <axis>
        <xyz>0 -1 0</xyz>
        <dynamics>
          <damping>0.002</damping>
        </dynamics>
      </axis>
      <physics>
        <ode>
          <implicit_spring_damper>1</implicit_spring_damper>
        </ode>
      </physics>
    </joint>

    <joint name="flap_left_joint" type="revolute">
      <parent>base_link</parent>
      <child>flap_left</child>
      <pose>0 -0.04 0 0 0 0</pose>
      <axis>
        <xyz>1 0.330321014 0</xyz>
        <limit>
          <lower>-0.524</lower>
          <upper>0.524</upper>
        </limit>
        <dynamics>
          <damping>0.1</damping>
        </dynamics>
      </axis>
      <physics>
        <ode>
          <implicit_spring_damper>1</implicit_spring_damper>
        </ode>
      </physics>
    </joint>

    <joint name="flap_right_joint" type="revolute">
      <parent>base_link</parent>
      <child>flap_right</child>
      <pose>0 -0.04 0 0 0 0</pose>
      <axis>
        <xyz>1 -0.330321014 0</xyz>
        <limit>
          <lower>-0.524</lower>
          <upper>0.524</upper>
        </limit>
        <dynamics>
          <damping>0.1</damping>
        </dynamics>
      </axis>
      <physics>
        <ode>
          <implicit_spring_damper>1</implicit_spring_damper>
        </ode>
      </physics>
    </joint>

    <plugin name="left_wing" filename="libLiftDragPlugin.so">
      <a0>0.05984281113</a0>
      <cla>4.752798721</cla>
      <cda>0.6417112299</cda>
      <cma>0.0</cma>
      <alpha_stall>0.3391428111</alpha_stall>
      <cla_stall>-3.85</cla_stall>
      <cda_stall>-0.9233984055</cda_stall>
      <cma_stall>0</cma_stall>
      <cp>-0.05 0.3 0.05</cp>
      <area>0.50</area>
      <air_density>1.2041</air_density>
      <forward>1 0 0</forward>
      <upward>0 0 1</upward>
      <link_name>base_link</link_name>
      <control_joint_name>
        flap_left_joint
      </control_joint_name>
      <control_joint_rad_to_cl>-1.0</control_joint_rad_to_cl>
      <robotNamespace></robotNamespace>
      <windSubTopic>/wind</windSubTopic>
    </plugin>
    <plugin name="right_wing" filename="libLiftDragPlugin.so">
      <a0>0.05984281113</a0>
      <cla>4.752798721</cla>
      <cda>0.6417112299</cda>
      <cma>0.0</cma>
      <alpha_stall>0.3391428111</alpha_stall>
      <cla_stall>-3.85</cla_stall>
      <cda_stall>-0.9233984055</cda_stall>
      <cma_stall>0</cma_stall>
      <cp>-0.05 -0.3 0.05</cp>
      <area>0.50</area>
      <air_density>1.2041</air_density>
      <forward>1 0 0</forward>
      <upward>0 0 1</upward>
      <link_name>base_link</link_name>
      <control_joint_name>
        flap_right_joint
      </control_joint_name>
      <control_joint_rad_to_cl>-1.0</control_joint_rad_to_cl>
      <robotNamespace></robotNamespace>
      <windSubTopic>/wind</windSubTopic>
    </plugin>
    <plugin name="left_rudder" filename="libLiftDragPlugin.so">
      <a0>0.0</a0>
      <cla>4.752798721</cla>
      <cda>0.6417112299</cda>
      <cma>0.0.</cma>
      <alpha_stall>0.3391428111</alpha_stall>
      <cla_stall>-3.85</cla_stall>
      <cda_stall>-0.9233984055</cda_stall>
      <cma_stall>0</cma_stall>
      <cp>-0.5 0 0.05</cp>
      <area>0.02</area>
      <air_density>1.2041</air_density>
      <forward>1 0 0</forward>
      <upward>0 1 0</upward>
      <link_name>base_link</link_name>
      <robotNamespace></robotNamespace>
      <windSubTopic>/wind</windSubTopic>
    </plugin>
    <plugin name="right_rudder" filename="libLiftDragPlugin.so">
      <a0>0.0</a0>
      <cla>4.752798721</cla>
      <cda>0.6417112299</cda>
      <cma>0.0.</cma>
      <alpha_stall>0.3391428111</alpha_stall>
      <cla_stall>-3.85</cla_stall>
      <cda_stall>-0.9233984055</cda_stall>
      <cma_stall>0</cma_stall>
      <cp>-0.5 0 0.05</cp>
      <area>0.02</area>
      <air_density>1.2041</air_density>
      <forward>1 0 0</forward>
      <upward>0 1 0</upward>
      <link_name>base_link</link_name>
      <robotNamespace></robotNamespace>
      <windSubTopic>/wind</windSubTopic>
    </plugin>
    <plugin name='puller' filename='libgazebo_motor_model.so'>
      <robotNamespace></robotNamespace>
      <jointName>propeller_joint</jointName>
      <linkName>propeller</linkName>
      <turningDirection>cw</turningDirection>
      <timeConstantUp>0.0125</timeConstantUp>
      <timeConstantDown>0.025</timeConstantDown>
      <maxRotVelocity>3500</maxRotVelocity>
      <motorConstant>8.54858e-06</motorConstant>
      <momentConstant>0.01</momentConstant>
      <commandSubTopic>/gazebo/command/motor_speed</commandSubTopic>
      <motorNumber>4</motorNumber>
      <rotorDragCoefficient>0.000106428</rotorDragCoefficient>
      <rollingMomentCoefficient>1e-06</rollingMomentCoefficient>
      <motorSpeedPubTopic>/motor_speed/4</motorSpeedPubTopic>
      <rotorVelocitySlowdownSim>20</rotorVelocitySlowdownSim>
    </plugin>
    <plugin name='gazebo_imu_plugin' filename='libgazebo_imu_plugin.so'>
      <robotNamespace></robotNamespace>
      <linkName>delta_wing/imu_link</linkName>
      <imuTopic>/imu</imuTopic>
      <gyroscopeNoiseDensity>0.0003394</gyroscopeNoiseDensity>
      <gyroscopeRandomWalk>3.8785e-05</gyroscopeRandomWalk>
      <gyroscopeBiasCorrelationTime>1000.0</gyroscopeBiasCorrelationTime>
      <gyroscopeTurnOnBiasSigma>0.0087</gyroscopeTurnOnBiasSigma>
      <accelerometerNoiseDensity>0.004</accelerometerNoiseDensity>
      <accelerometerRandomWalk>0.006</accelerometerRandomWalk>
      <accelerometerBiasCorrelationTime>300.0</accelerometerBiasCorrelationTime>
      <accelerometerTurnOnBiasSigma>0.196</accelerometerTurnOnBiasSigma>
    </plugin>
    <plugin name="gps_plugin" filename="libgazebo_gps_plugin.so">
        <robotNamespace></robotNamespace>
        <gpsNoise>true</gpsNoise>
    </plugin>
    <plugin name='magnetometer_plugin' filename='libgazebo_magnetometer_plugin.so'>
      <robotNamespace/>
      <pubRate>100</pubRate>
      <noiseDensity>0.0004</noiseDensity>
      <randomWalk>6.4e-06</randomWalk>
      <biasCorrelationTime>600</biasCorrelationTime>
      <magTopic>/mag</magTopic>
    </plugin>
    <plugin name='barometer_plugin' filename='libgazebo_barometer_plugin.so'>
      <robotNamespace/>
      <pubRate>50</pubRate>
      <baroTopic>/baro</baroTopic>
    </plugin>
    <plugin name='airspeed_plugin' filename='libgazebo_airspeed_plugin.so'>
      <robotNamespace/>
      <linkName>delta_wing/airspeed_link</linkName>
    </plugin>
    <plugin name='mavlink_interface' filename='libgazebo_mavlink_interface.so'>
      <robotNamespace></robotNamespace>
      <imuSubTopic>/imu</imuSubTopic>
      <gpsSubTopic>/gps</gpsSubTopic>
      <magSubTopic>/mag</magSubTopic>
      <baroSubTopic>/baro</baroSubTopic>
      <mavlink_addr>INADDR_ANY</mavlink_addr>
      <mavlink_udp_port>14560</mavlink_udp_port>
      <serialEnabled>false</serialEnabled>
      <serialDevice>/dev/ttyACM0</serialDevice>
      <baudRate>921600</baudRate>
      <qgc_addr>INADDR_ANY</qgc_addr>
      <qgc_udp_port>14550</qgc_udp_port>
      <sdk_addr>INADDR_ANY</sdk_addr>
      <sdk_udp_port>14540</sdk_udp_port>
      <hil_mode>false</hil_mode>
      <hil_state_level>false</hil_state_level>
      <enable_lockstep>true</enable_lockstep>
      <use_tcp>true</use_tcp>
      <motorSpeedCommandPubTopic>/gazebo/command/motor_speed</motorSpeedCommandPubTopic>
      <control_channels>
        <channel name="rotor4">
          <input_index>4</input_index>
          <input_offset>0</input_offset>
          <input_scaling>3500</input_scaling>
          <zero_position_disarmed>0</zero_position_disarmed>
          <zero_position_armed>0</zero_position_armed>
          <joint_control_type>velocity</joint_control_type>
          <joint_name>propeller_joint</joint_name>
        </channel>
        <channel name="left_elevon">
          <input_index>5</input_index>
          <input_offset>0</input_offset>
          <input_scaling>1</input_scaling>
          <zero_position_disarmed>0</zero_position_disarmed>
          <zero_position_armed>0</zero_position_armed>
          <joint_control_type>position_kinematic</joint_control_type>
          <joint_name>left_flap_joint</joint_name>
        </channel>
        <channel name="right_elevon">
          <input_index>6</input_index>
          <input_offset>0</input_offset>
          <input_scaling>1</input_scaling>
          <zero_position_disarmed>0</zero_position_disarmed>
          <zero_position_armed>0</zero_position_armed>
          <joint_control_type>position_kinematic</joint_control_type>
          <joint_name>right_flap_joint</joint_name>
        </channel>
      </control_channels>
    </plugin>
    <static>0</static>
  </model>
</sdf>
